Workbook

Sheet Executive Dashboard
A1: PRIME BISTRO — EXECUTIVE DASHBOARD
A2: F&B Controlling System | Live — updates automatically as data is entered
A4: 1. MONTHLY SALES & PROFIT SNAPSHOT
A6: FOOD SALES (ETB) | D6: BEVERAGE SALES (ETB) | G6: GROSS SALES (ETB) | J6: NET SALES (ETB)
A7: ='Daily Flash Cost'!AG4 -> 224090 | D7: ='Daily Flash Cost'!AG5 -> 82140 | G7: ='Daily Flash Cost'!AG6 -> 306230 | J7: ='Daily Flash Cost'!AG9 -> 305330
A9: TOTAL ACTUAL COST (ETB) | D9: GROSS PROFIT (ETB) | G9: OVERALL F&B COST % | J9: GROSS PROFIT %
A10: ='Daily Flash Cost'!AG15 -> 107557.6 | D10: ='Daily Flash Cost'!AG20 -> 211104.09 | G10: ='Daily Flash Cost'!AG23 -> 0.35123144 | J10: =IFERROR('Daily Flash Cost'!AG20/'Daily Flash Cost'!AG9,0) -> 0.69139649
A12: FOOD COST % | D12: BEVERAGE COST % | G12: AVG. DAILY NET SALES (ETB) | J12: DAYS OF DATA (Month)
A13: ='Daily Flash Cost'!AG21 -> 0.33492513 | D13: ='Daily Flash Cost'!AG22 -> 0.39571744 | G13: =IFERROR('Daily Flash Cost'!AG9/COUNTIF('Daily Flash Cost'!B3:AF3,"<>"),0) -> 9849.3548 | J13: =COUNT('Daily Flash Cost'!B4:AF4) -> 31
A16: 2. LOSS & VARIANCE CONTROL
A18: TOTAL WASTAGE VALUE (ETB) | D18: STAFF MEAL COST (ETB) | G18: VOID + COMP SALES (ETB) | J18: INVENTORY VARIANCE COST (ETB)
A19: =SUM(Wastage!$I:$I) -> 219.5 | D19: =SUM('Daily Staff Meal'!$H:$H) -> 1188 | G19: =SUM('Daily Void'!$J:$J)+SUM(Complementary!$J:$J) -> 900 | J19: =SUM('Inventory Variance'!$I:$I) -> -14739.195
A21: RECIPE VARIANCE COST (ETB) | D21: ITEMS TO INVESTIGATE (Variance) | G21: WASTAGE EVENTS LOGGED | J21: VOID EVENTS LOGGED
A22: =SUM('Theoretical Consumption'!$M:$M) -> 21671.133 | D22: =COUNTIF('Inventory Variance'!$K:$K,"INVESTIGATE") -> 33 | G22: =COUNTA(Wastage!$C$5:$C$64) -> 4 | J22: =COUNTA('Daily Void'!$E$5:$E$44) -> 2
A25: 3. MAIN STORE INVENTORY HEALTH (Par Level Monitoring)
A27: TOTAL STORE VALUE (ETB) | D27: ITEMS BELOW MIN PAR | G27: ITEMS OVERSTOCKED | J27: ITEMS WITHIN PAR (OK)
A28: =SUM('Store Inventory'!G4:G41) -> 230960 | D28: =COUNTIF('Store Inventory'!J4:J41,"REORDER NOW") -> 8 | G28: =COUNTIF('Store Inventory'!J4:J41,"OVERSTOCK") -> 21 | J28: =COUNTIF('Store Inventory'!J4:J41,"OK") -> 6
A30: TOP REORDER ALERTS (Main Store)
A31: Item | B31: Category | C31: Available Qty | D31: Min Par | E31: Status
A32: =IFERROR(INDEX('Store Inventory'!$B$4:$B$41,MATCH(1,'Store Inventory'!$L$4:$L$41,0)),"—") -> Black Tea Bags | B32: =IFERROR(INDEX('Store Inventory'!$C$4:$C$41,MATCH(1,'Store Inventory'!$L$4:$L$41,0)),"") -> Coffee & Tea | C32: =IFERROR(INDEX('Store Inventory'!$E$4:$E$41,MATCH(1,'Store Inventory'!$L$4:$L$41,0)),"") -> 0 | D32: =IFERROR(INDEX('Store Inventory'!$H$4:$H$41,MATCH(1,'Store Inventory'!$L$4:$L$41,0)),"") -> 20 | E32: =IF(A32="—","","REORDER NOW") -> REORDER NOW
A33: =IFERROR(INDEX('Store Inventory'!$B$4:$B$41,MATCH(2,'Store Inventory'!$L$4:$L$41,0)),"—") -> Green Tea Bags | B33: =IFERROR(INDEX('Store Inventory'!$C$4:$C$41,MATCH(2,'Store Inventory'!$L$4:$L$41,0)),"") -> Coffee & Tea | C33: =IFERROR(INDEX('Store Inventory'!$E$4:$E$41,MATCH(2,'Store Inventory'!$L$4:$L$41,0)),"") -> 0 | D33: =IFERROR(INDEX('Store Inventory'!$H$4:$H$41,MATCH(2,'Store Inventory'!$L$4:$L$41,0)),"") -> 20 | E33: =IF(A33="—","","REORDER NOW") -> REORDER NOW
A34: =IFERROR(INDEX('Store Inventory'!$B$4:$B$41,MATCH(3,'Store Inventory'!$L$4:$L$41,0)),"—") -> Cocoa Powder | B34: =IFERROR(INDEX('Store Inventory'!$C$4:$C$41,MATCH(3,'Store Inventory'!$L$4:$L$41,0)),"") -> Coffee & Tea | C34: =IFERROR(INDEX('Store Inventory'!$E$4:$E$41,MATCH(3,'Store Inventory'!$L$4:$L$41,0)),"") -> 0 | D34: =IFERROR(INDEX('Store Inventory'!$H$4:$H$41,MATCH(3,'Store Inventory'!$L$4:$L$41,0)),"") -> 10 | E34: =IF(A34="—","","REORDER NOW") -> REORDER NOW
A35: =IFERROR(INDEX('Store Inventory'!$B$4:$B$41,MATCH(4,'Store Inventory'!$L$4:$L$41,0)),"—") -> Fresh Mint Leaves | B35: =IFERROR(INDEX('Store Inventory'!$C$4:$C$41,MATCH(4,'Store Inventory'!$L$4:$L$41,0)),"") -> Bar Garnish | C35: =IFERROR(INDEX('Store Inventory'!$E$4:$E$41,MATCH(4,'Store Inventory'!$L$4:$L$41,0)),"") -> 0 | D35: =IFERROR(INDEX('Store Inventory'!$H$4:$H$41,MATCH(4,'Store Inventory'!$L$4:$L$41,0)),"") -> 10 | E35: =IF(A35="—","","REORDER NOW") -> REORDER NOW
A36: =IFERROR(INDEX('Store Inventory'!$B$4:$B$41,MATCH(5,'Store Inventory'!$L$4:$L$41,0)),"—") -> Paper Napkins | B36: =IFERROR(INDEX('Store Inventory'!$C$4:$C$41,MATCH(5,'Store Inventory'!$L$4:$L$41,0)),"") -> Consumables | C36: =IFERROR(INDEX('Store Inventory'!$E$4:$E$41,MATCH(5,'Store Inventory'!$L$4:$L$41,0)),"") -> 0 | D36: =IFERROR(INDEX('Store Inventory'!$H$4:$H$41,MATCH(5,'Store Inventory'!$L$4:$L$41,0)),"") -> 100 | E36: =IF(A36="—","","REORDER NOW") -> REORDER NOW
A38: 4. MENU PORTFOLIO OVERVIEW
A40: TOTAL ACTIVE MENU ITEMS | D40: STARS | G40: PLOWHORSES | J40: PUZZLES + DOGS
A41: 26 | D41: =COUNTIF('Menu Engineering'!$J$4:$J$29,"STAR") -> 3 | G41: =COUNTIF('Menu Engineering'!$J$4:$J$29,"PLOWHORSE") -> 6 | J41: =COUNTIF('Menu Engineering'!$J$4:$J$29,"PUZZLE")+COUNTIF('Menu Engineering'!$J$4:$J$29,"DOG") -> 17
A43: TOP 5 BEST SELLERS (by Qty Sold) | G43: TOP 5 REVENUE DRIVERS (by Monthly Sales)
A44: Menu Item | B44: Category | C44: Qty Sold | G44: Menu Item | H44: Category | I44: Revenue (ETB)
A45: =IFERROR(INDEX('Menu Engineering'!$B$4:$B$29,MATCH(1,'Menu Engineering'!$M$4:$M$29,0)),"—") -> Cappuccino | B45: =IFERROR(INDEX('Menu Engineering'!$C$4:$C$29,MATCH(1,'Menu Engineering'!$M$4:$M$29,0)),"") -> Beverage | C45: =IFERROR(INDEX('Menu Engineering'!$D$4:$D$29,MATCH(1,'Menu Engineering'!$M$4:$M$29,0)),"") -> 157 | G45: =IFERROR(INDEX('Menu Engineering'!$B$4:$B$29,MATCH(1,'Menu Engineering'!$N$4:$N$29,0)),"—") -> Margherita Pizza | H45: =IFERROR(INDEX('Menu Engineering'!$C$4:$C$29,MATCH(1,'Menu Engineering'!$N$4:$N$29,0)),"") -> Food | I45: =IFERROR(INDEX('Menu Engineering'!$L$4:$L$29,MATCH(1,'Menu Engineering'!$N$4:$N$29,0)),"") -> 31160
A46: =IFERROR(INDEX('Menu Engineering'!$B$4:$B$29,MATCH(2,'Menu Engineering'!$M$4:$M$29,0)),"—") -> Americano | B46: =IFERROR(INDEX('Menu Engineering'!$C$4:$C$29,MATCH(2,'Menu Engineering'!$M$4:$M$29,0)),"") -> Beverage | C46: =IFERROR(INDEX('Menu Engineering'!$D$4:$D$29,MATCH(2,'Menu Engineering'!$M$4:$M$29,0)),"") -> 137 | G46: =IFERROR(INDEX('Menu Engineering'!$B$4:$B$29,MATCH(2,'Menu Engineering'!$N$4:$N$29,0)),"—") -> Classic Beef Burger | H46: =IFERROR(INDEX('Menu Engineering'!$C$4:$C$29,MATCH(2,'Menu Engineering'!$N$4:$N$29,0)),"") -> Food | I46: =IFERROR(INDEX('Menu Engineering'!$L$4:$L$29,MATCH(2,'Menu Engineering'!$N$4:$N$29,0)),"") -> 29120
A47: =IFERROR(INDEX('Menu Engineering'!$B$4:$B$29,MATCH(3,'Menu Engineering'!$M$4:$M$29,0)),"—") -> Coca-Cola | B47: =IFERROR(INDEX('Menu Engineering'!$C$4:$C$29,MATCH(3,'Menu Engineering'!$M$4:$M$29,0)),"") -> Beverage | C47: =IFERROR(INDEX('Menu Engineering'!$D$4:$D$29,MATCH(3,'Menu Engineering'!$M$4:$M$29,0)),"") -> 103 | G47: =IFERROR(INDEX('Menu Engineering'!$B$4:$B$29,MATCH(3,'Menu Engineering'!$N$4:$N$29,0)),"—") -> Spaghetti Bolognese | H47: =IFERROR(INDEX('Menu Engineering'!$C$4:$C$29,MATCH(3,'Menu Engineering'!$N$4:$N$29,0)),"") -> Food | I47: =IFERROR(INDEX('Menu Engineering'!$L$4:$L$29,MATCH(3,'Menu Engineering'!$N$4:$N$29,0)),"") -> 23100
A48: =IFERROR(INDEX('Menu Engineering'!$B$4:$B$29,MATCH(4,'Menu Engineering'!$M$4:$M$29,0)),"—") -> Classic Beef Burger | B48: =IFERROR(INDEX('Menu Engineering'!$C$4:$C$29,MATCH(4,'Menu Engineering'!$M$4:$M$29,0)),"") -> Food | C48: =IFERROR(INDEX('Menu Engineering'!$D$4:$D$29,MATCH(4,'Menu Engineering'!$M$4:$M$29,0)),"") -> 91 | G48: =IFERROR(INDEX('Menu Engineering'!$B$4:$B$29,MATCH(4,'Menu Engineering'!$N$4:$N$29,0)),"—") -> Cappuccino | H48: =IFERROR(INDEX('Menu Engineering'!$C$4:$C$29,MATCH(4,'Menu Engineering'!$N$4:$N$29,0)),"") -> Beverage | I48: =IFERROR(INDEX('Menu Engineering'!$L$4:$L$29,MATCH(4,'Menu Engineering'!$N$4:$N$29,0)),"") -> 17270
A49: =IFERROR(INDEX('Menu Engineering'!$B$4:$B$29,MATCH(5,'Menu Engineering'!$M$4:$M$29,0)),"—") -> Butter Croissant | B49: =IFERROR(INDEX('Menu Engineering'!$C$4:$C$29,MATCH(5,'Menu Engineering'!$M$4:$M$29,0)),"") -> Food | C49: =IFERROR(INDEX('Menu Engineering'!$D$4:$D$29,MATCH(5,'Menu Engineering'!$M$4:$M$29,0)),"") -> 85 | G49: =IFERROR(INDEX('Menu Engineering'!$B$4:$B$29,MATCH(5,'Menu Engineering'!$N$4:$N$29,0)),"—") -> Double Beef Burger | H49: =IFERROR(INDEX('Menu Engineering'!$C$4:$C$29,MATCH(5,'Menu Engineering'!$N$4:$N$29,0)),"") -> Food | I49: =IFERROR(INDEX('Menu Engineering'!$L$4:$L$29,MATCH(5,'Menu Engineering'!$N$4:$N$29,0)),"") -> 17220
A51: 5. NOTES
A53: All figures on this dashboard are live formulas pulling from Daily Sales, Daily Flash Cost, Store Inventory, Wastage, Daily Void, Complementary, Daily Staff Meal, Inventory Variance, Theoretical Consumption and Menu Engineering. Enter your outlet's real daily data in those sheets and every number here recalculates automatically — nothing on this page needs to be typed in directly.

Sheet Overview
A1: PRIME BISTRO — F&B CONTROLLING SYSTEM
A2: System Guide & Overview
B4: 1. PURPOSE OF THIS SYSTEM
B5: This workbook is the complete F&B costing and control system for Prime Bistro, rebuilt for a SINGLE OUTLET. It exists to answer, every day, three questions: what did we sell, what did it cost us, and where is money being lost — so food cost can be actively managed rather than discovered a month later.
B7: 2. HOW THE SINGLE-STORE, SINGLE-OUTLET MODEL WORKS
B8: All ingredients are purchased into and valued in one Main Store (moving-average costing). The Main Store issues stock to the outlet's Kitchen & Bar, which is where daily consumption, sales, and wastage are tracked.
B10: 3. THE FLOW OF THE SYSTEM (follow the sheets in this order)
B11: Item Master | C11: Master list of every raw ingredient (Food / Beverage / Others) with standard cost, used to build recipes.
B12: Menu Master | C12: Every sellable menu item (Food, Beverage, To-Go). This is what recipes and daily sales are built from.
B13: Recipe Master | C13: Ingredient breakdown + standard cost for every menu item — the basis of theoretical food cost.
B14: Sub-Recipe | C14: Homemade components (buns, dressings, sauces, dough) costed separately, then used inside Recipe Master.
B15: Purchase Register | C15: What was bought, from whom, at what cost — feeds the Main Store.
B16: Store Receiving | C16: Goods received into the Main Store, building up available stock and average cost.
B17: Store Inventory | C17: The Main Store balance — with Min/Max Par Level and an automatic Reorder Status flag.
B18: Store Issue | C18: Stock issued from the Main Store to the outlet's Kitchen & Bar.
B19: Kitchen & Bar Receiving | C19: Confirms what the outlet actually received from the Main Store.
B20: Daily Inventory / Semi-Finished Inventory | C20: Daily stock counts at the outlet, for raw items and homemade prep items.
B21: Wastage / Daily Void / Complementary / Staff Meal | C21: Every way food leaves the building without being paid for in full.
B22: Daily Sales | C22: Every menu item sold, day by day for the month — the engine of the whole system.
... B26: Executive Dashboard | C26: One-page view of every major KPI above, updating live as data is entered.
B28: 4. HOW ITEM MASTER, MENU MASTER, RECIPE MASTER AND SUB-RECIPE FIT TOGETHER
B29: Item Master is built to serve Menu Master: every raw ingredient in Item Master exists because it is needed by a recipe on Menu Master. A Sub-Recipe is any homemade component — burger buns, sandwich bread, pizza dough, bolognese/alfredo/pizza sauce, caesar dressing, mojito syrup — costed once as its own small recipe with a batch yield, then pulled into Recipe Master as a single costed ingredient line. Whenever a new menu item is added: add its raw ingredients to Item Master (if not already there), cost any new homemade component in Sub-Recipe, then build its line in Recipe Master — the rest of the system (Daily Sales standard cost, Flash Cost, Menu Engineering, Theoretical Consumption) picks it up automatically.
B31: 5. MAIN STORE PAR LEVELS
B32: Every item in Store Inventory carries a Min Par Level and Max Par Level. A Reorder Status column flags each item automatically as REORDER NOW (below minimum), OVERSTOCK (above maximum) or OK — colour-coded so the purchaser can act at a glance instead of reading raw numbers.
B34: 6. COLOUR KEY USED THROUGHOUT THE SYSTEM
B35: Blue text = a cell you type into (inputs, prices, par levels, quantities, dates). Black text = an automatic formula — never overtype these. Green text = a live link pulled from another sheet. Shaded rows = subtotal / total rows. Yellow-tinted cells = key assumptions.
B37: 7. TRIAL DATA IN THIS FILE
B38: Every transactional sheet (Purchase Register, Store Receiving, Store Issue, Daily Sales, Wastage, Void, Complementary, Staff Meal, Daily Inventory) has been pre-filled with realistic sample data for the first few days/events of the month so you can see the whole system working end-to-end — every report, variance and the Executive Dashboard are already live. Simply clear the blue input cells and replace them with your own outlet's real numbers; every formula will recalculate automatically.

Sheet Item Master
A1: ITEM MASTER
A2: Master list of every raw ingredient — standard cost feeds every recipe
A3: ITEM CODE | B3: ITEM NAME | C3: CATEGORY | D3: UOM | E3: STANDARD COST (ETB)
A4: FOOD
A5: FD001 | B5: Beef Mince (80% Lean) | C5: Meat & Poultry | D5: Kg | E5: 550
A6: FD002 | B6: Chicken Breast (Boneless) | C6: Meat & Poultry | D6: Kg | E6: 480
A7: FD003 | B7: Bacon Strips | C7: Meat & Poultry | D7: Kg | E7: 650
A8: FD004 | B8: Fresh Lettuce | C8: Fresh Produce | D8: Kg | E8: 60
A9: FD005 | B9: Fresh Tomato | C9: Fresh Produce | D9: Kg | E9: 55
A10: FD006 | B10: Onion | C10: Fresh Produce | D10: Kg | E10: 40
A11: FD007 | B11: Cheddar Cheese Slice | C11: Dairy | D11: Pcs | E11: 12
A12: FD008 | B12: All-Purpose Flour | C12: Bakery & Dry Goods | D12: Kg | E12: 55
A13: FD009 | B13: Butter (Unsalted) | C13: Dairy | D13: Kg | E13: 480
A14: FD010 | B14: Fresh Eggs | C14: Dairy | D14: Pcs | E14: 8
A15: FD011 | B15: Spaghetti Pasta | C15: Bakery & Dry Goods | D15: Kg | E15: 120
A16: FD012 | B16: Tortilla Wrap | C16: Bakery & Dry Goods | D16: Pcs | E16: 15
... A19: FD015 | B19: Mozzarella Cheese | C19: Dairy | D19: Kg | E19: 620
A20: BEVERAGE
A21: BV001 | B21: Coffee Beans (Roasted) | C21: Coffee & Tea | D21: Kg | E21: 900
A22: BV002 | B22: Black Tea Bags | C22: Coffee & Tea | D22: Pcs | E22: 3
A23: BV003 | B23: Green Tea Bags | C23: Coffee & Tea | D23: Pcs | E23: 4
A24: BV004 | B24: Fresh Milk | C24: Dairy & Bar | D24: Ltr | E24: 65
A25: BV005 | B25: Cocoa Powder | C25: Coffee & Tea | D25: Kg | E25: 350
A26: BV006 | B26: White Rum | C26: Bar & Spirits | D26: Ltr | E26: 950
A27: BV007 | B27: Fresh Mint Leaves | C27: Bar Garnish | D27: Kg | E27: 150
A28: BV008 | B28: Fresh Lime | C28: Bar Garnish | D28: Kg | E28: 100
A29: BV009 | B29: Fresh Avocado | C29: Fresh Produce | D29: Kg | E29: 90
A30: BV010 | B30: Soda Water | C30: Bar & Mixers | D30: Ltr | E30: 45
A31: BV011 | B31: Coca-Cola (330ml Bottle) | C31: Soft Drinks | D31: Bottle | E31: 35
A32: OTHERS
A33: OT001 | B33: Burger Takeaway Box | C33: Packaging | D33: Pcs | E33: 8
A34: OT002 | B34: Pizza Takeaway Box | C34: Packaging | D34: Pcs | E34: 15
A35: OT003 | B35: Paper Napkins | C35: Consumables | D35: Pcs | E35: 1
A36: OT004 | B36: Disposable Straws | C36: Consumables | D36: Pcs | E36: 1
A37: OT005 | B37: White Sugar | C37: Pantry & Dry Goods | D37: Kg | E37: 60
A38: OT006 | B38: Iodized Salt | C38: Pantry & Dry Goods | D38: Kg | E38: 25
A39: OT007 | B39: Cooking / Vegetable Oil | C39: Pantry & Dry Goods | D39: Ltr | E39: 150
A40: OT008 | B40: Instant Dry Yeast | C40: Pantry & Dry Goods | D40: Kg | E40: 400
A41: OT009 | B41: Black Pepper (Ground) | C41: Pantry & Dry Goods | D41: Kg | E41: 500

Sheet Menu Master
A1: MENU MASTER
A2: Every sellable menu item — the basis of Recipe Master & Daily Sales
A3: MENU CODE | B3: MENU ITEM | C3: CATEGORY | D3: SUB-CATEGORY | E3: UOM | F3: STATUS
A4: A. Food Menu
A5: Burgers
A6: FM001 | B6: Classic Beef Burger | C6: Food | D6: Burger | E6: Plate | F6: Active
A7: FM002 | B7: Double Beef Burger | C7: Food | D7: Burger | E7: Plate | F7: Active
A8: Wraps
A9: FM003 | B9: Chicken Caesar Wrap | C9: Food | D9: Wrap | E9: Plate | F9: Active
A10: FM004 | B10: Crispy Chicken Wrap | C10: Food | D10: Wrap | E10: Plate | F10: Active
A11: Sandwiches
A12: FM005 | B12: Club Sandwich | C12: Food | D12: Sandwich | E12: Plate | F12: Active
A13: FM006 | B13: Chicken Sandwich | C13: Food | D13: Sandwich | E13: Plate | F13: Active
A14: Pasta
A15: FM007 | B15: Spaghetti Bolognese | C15: Food | D15: Pasta | E15: Plate | F15: Active
A16: FM008 | B16: Spaghetti Alfredo | C16: Food | D16: Pasta | E16: Plate | F16: Active
A17: Breakfast
A18: FM009 | B18: American Breakfast | C18: Food | D18: Breakfast | E18: Plate | F18: Active
A19: FM010 | B19: Continental Breakfast | C19: Food | D19: Breakfast | E19: Plate | F19: Active
A20: Bakery & Pastries
A21: FM011 | B21: Butter Croissant | C21: Food | D21: Bakery & Pastries | E21: Plate | F21: Active
A22: FM012 | B22: Danish Pastry | C22: Food | D22: Bakery & Pastries | E22: Plate | F22: Active
A23: Salads
A24: FM013 | B24: Chicken Caesar Salad | C24: Food | D24: Salad | E24: Plate | F24: Active
A25: FM014 | B25: Avocado Salad | C25: Food | D25: Salad | E25: Plate | F25: Active
A26: Pizza
A27: FM015 | B27: Margherita Pizza | C27: Food | D27: Pizza | E27: Plate | F27: Active
A28: B. Beverage Menu
A29: Coffee
A30: BM001 | B30: Americano | C30: Beverage | D30: Coffee | E30: Cup | F30: Active
A31: BM002 | B31: Cappuccino | C31: Beverage | D31: Coffee | E31: Cup | F31: Active
A32: Tea
A33: BM003 | B33: English Breakfast Tea | C33: Beverage | D33: Tea | E33: Cup | F33: Active
A34: BM004 | B34: Green Tea | C34: Beverage | D34: Tea | E34: Cup | F34: Active
A35: Hot Drinks
A36: BM005 | B36: Hot Chocolate | C36: Beverage | D36: Hot Drink | E36: Cup | F36: Active
A37: Mojitos
A38: BM006 | B38: Classic Mojito | C38: Beverage | D38: Mojito | E38: Glass | F38: Active
A39: BM007 | B39: Strawberry Mojito | C39: Beverage | D39: Mojito | E39: Glass | F39: Active
A40: Fresh Juices
...

Sheet Recipe Master
A1: RECIPE MASTER
A2: Ingredient breakdown & standard cost for every menu item — theoretical food cost engine
A3: RECIPE CODE | B3: MENU CODE | C3: MENU ITEM | D3: ITEM CODE | E3: INGREDIENT | F3: UOM | G3: QTY | H3: ITEM COST (ETB) | I3: MONTHLY QTY SOLD (link) | J3: THEORETICAL QTY THIS LINE
A4: RC-FM001 | B4: FM001 | C4: Classic Beef Burger | D4: FD001 | E4: Beef Mince (80% Lean) | F4: Kg | G4: 0.15 | H4: =G4*IFERROR(INDEX('Item Master'!$E$4:$E$41,MATCH(D4,'Item Master'!$A$4:$A$41,0)),INDEX('Sub-Recipe'!$K$4:$K$200,MATCH(D4,'Sub-Recipe'!$A$4:$A$200,0))) -> 82.5 | I4: =IFERROR(INDEX('Daily Sales'!$AK$5:$AK$30,MATCH($B4,'Daily Sales'!$A$5:$A$30,0)),0) -> 91 | J4: =G4*I4 -> 13.65
A5: RC-FM001 | B5: FM001 | C5: Classic Beef Burger | D5: SR001 | E5: TOTAL - Burger Bun (Homemade) (Sub-Recipe) | F5: Pcs | G5: 1 | H5: =G5*IFERROR(INDEX('Item Master'!$E$4:$E$41,MATCH(D5,'Item Master'!$A$4:$A$41,0)),INDEX('Sub-Recipe'!$K$4:$K$200,MATCH(D5,'Sub-Recipe'!$A$4:$A$200,0))) -> 0 | I5: =IFERROR(INDEX('Daily Sales'!$AK$5:$AK$30,MATCH($B5,'Daily Sales'!$A$5:$A$30,0)),0) -> 91 | J5: =G5*I5 -> 91
A6: RC-FM001 | B6: FM001 | C6: Classic Beef Burger | D6: FD004 | E6: Fresh Lettuce | F6: Kg | G6: 0.02 | H6: =G6*IFERROR(INDEX('Item Master'!$E$4:$E$41,MATCH(D6,'Item Master'!$A$4:$A$41,0)),INDEX('Sub-Recipe'!$K$4:$K$200,MATCH(D6,'Sub-Recipe'!$A$4:$A$200,0))) -> 1.2 | I6: =IFERROR(INDEX('Daily Sales'!$AK$5:$AK$30,MATCH($B6,'Daily Sales'!$A$5:$A$30,0)),0) -> 91 | J6: =G6*I6 -> 1.82
A7: RC-FM001 | B7: FM001 | C7: Classic Beef Burger | D7: FD005 | E7: Fresh Tomato | F7: Kg | G7: 0.03 | H7: =G7*IFERROR(INDEX('Item Master'!$E$4:$E$41,MATCH(D7,'Item Master'!$A$4:$A$41,0)),INDEX('Sub-Recipe'!$K$4:$K$200,MATCH(D7,'Sub-Recipe'!$A$4:$A$200,0))) -> 1.65 | I7: =IFERROR(INDEX('Daily Sales'!$AK$5:$AK$30,MATCH($B7,'Daily Sales'!$A$5:$A$30,0)),0) -> 91 | J7: =G7*I7 -> 2.73
A8: RC-FM001 | B8: FM001 | C8: Classic Beef Burger | D8: FD006 | E8: Onion | F8: Kg | G8: 0.02 | H8: =G8*IFERROR(INDEX('Item Master'!$E$4:$E$41,MATCH(D8,'Item Master'!$A$4:$A$41,0)),INDEX('Sub-Recipe'!$K$4:$K$200,MATCH(D8,'Sub-Recipe'!$A$4:$A$200,0))) -> 0.8 | I8: =IFERROR(INDEX('Daily Sales'!$AK$5:$AK$30,MATCH($B8,'Daily Sales'!$A$5:$A$30,0)),0) -> 91 | J8: =G8*I8 -> 1.82
A9: RC-FM001 | B9: FM001 | C9: Classic Beef Burger | D9: FD007 | E9: Cheddar Cheese Slice | F9: Pcs | G9: 1 | H9: =G9*IFERROR(INDEX('Item Master'!$E$4:$E$41,MATCH(D9,'Item Master'!$A$4:$A$41,0)),INDEX('Sub-Recipe'!$K$4:$K$200,MATCH(D9,'Sub-Recipe'!$A$4:$A$200,0))) -> 12 | I9: =IFERROR(INDEX('Daily Sales'!$AK$5:$AK$30,MATCH($B9,'Daily Sales'!$A$5:$A$30,0)),0) -> 91 | J9: =G9*I9 -> 91
A10: RC-FM001 | B10: FM001 | C10: Classic Beef Burger | D10: FD013 | E10: Mayonnaise | F10: Kg | G10: 0.02 | H10: =G10*IFERROR(INDEX('Item Master'!$E$4:$E$41,MATCH(D10,'Item Master'!$A$4:$A$41,0)),INDEX('Sub-Recipe'!$K$4:$K$200,MATCH(D10,'Sub-Recipe'!$A$4:$A$200,0))) -> 4.4 | I10: =IFERROR(INDEX('Daily Sales'!$AK$5:$AK$30,MATCH($B10,'Daily Sales'!$A$5:$A$30,0)),0) -> 91 | J10: =G10*I10 -> 1.82
A11: RC-FM001 | B11: FM001 | C11: Classic Beef Burger | D11: FD014 | E11: Tomato Ketchup | F11: Kg | G11: 0.02 | H11: =G11*IFERROR(INDEX('Item Master'!$E$4:$E$41,MATCH(D11,'Item Master'!$A$4:$A$41,0)),INDEX('Sub-Recipe'!$K$4:$K$200,MATCH(D11,'Sub-Recipe'!$A$4:$A$200,0))) -> 3.6 | I11: =IFERROR(INDEX('Daily Sales'!$AK$5:$AK$30,MATCH($B11,'Daily Sales'!$A$5:$A$30,0)),0) -> 91 | J11: =G11*I11 -> 1.82
A12: RC-FM001 | B12: FM001 | C12: TOTAL STANDARD RECIPE COST - Classic Beef Burger | D12: TOTAL | H12: =SUM(H4:H11) -> 106.15
A14: RC-FM002 | B14: FM002 | C14: Double Beef Burger | D14: FD001 | E14: Beef Mince (80% Lean) | F14: Kg | G14: 0.3 | H14: =G14*IFERROR(INDEX('Item Master'!$E$4:$E$41,MATCH(D14,'Item Master'!$A$4:$A$41,0)),INDEX('Sub-Recipe'!$K$4:$K$200,MATCH(D14,'Sub-Recipe'!$A$4:$A$200,0))) -> 165 | I14: =IFERROR(INDEX('Daily Sales'!$AK$5:$AK$30,MATCH($B14,'Daily Sales'!$A$5:$A$30,0)),0) -> 41 | J14: =G14*I14 -> 12.3
A15: RC-FM002 | B15: FM002 | C15: Double Beef Burger | D15: SR001 | E15: TOTAL - Burger Bun (Homemade) (Sub-Recipe) | F15: Pcs | G15: 1 | H15: =G15*IFERROR(INDEX('Item Master'!$E$4:$E$41,MATCH(D15,'Item Master'!$A$4:$A$41,0)),INDEX('Sub-Recipe'!$K$4:$K$200,MATCH(D15,'Sub-Recipe'!$A$4:$A$200,0))) -> 0 | I15: =IFERROR(INDEX('Daily Sales'!$AK$5:$AK$30,MATCH($B15,'Daily Sales'!$A$5:$A$30,0)),0) -> 41 | J15: =G15*I15 -> 41
A16: RC-FM002 | B16: FM002 | C16: Double Beef Burger | D16: FD004 | E16: Fresh Lettuce | F16: Kg | G16: 0.02 | H16: =G16*IFERROR(INDEX('Item Master'!$E$4:$E$41,MATCH(D16,'Item Master'!$A$4:$A$41,0)),INDEX('Sub-Recipe'!$K$4:$K$200,MATCH(D16,'Sub-Recipe'!$A$4:$A$200,0))) -> 1.2 | I16: =IFERROR(INDEX('Daily Sales'!$AK$5:$AK$30,MATCH($B16,'Daily Sales'!$A$5:$A$30,0)),0) -> 41 | J16: =G16*I16 -> 0.82
A17: RC-FM002 | B17: FM002 | C17: Double Beef Burger | D17: FD005 | E17: Fresh Tomato | F17: Kg | G17: 0.03 | H17: =G17*IFERROR(INDEX('Item Master'!$E$4:$E$41,MATCH(D17,'Item Master'!$A$4:$A$41,0)),INDEX('Sub-Recipe'!$K$4:$K$200,MATCH(D17,'Sub-Recipe'!$A$4:$A$200,0))) -> 1.65 | I17: =IFERROR(INDEX('Daily Sales'!$AK$5:$AK$30,MATCH($B17,'Daily Sales'!$A$5:$A$30,0)),0) -> 41 | J17: =G17*I17 -> 1.23
A18: RC-FM002 | B18: FM002 | C18: Double Beef Burger | D18: FD006 | E18: Onion | F18: Kg | G18: 0.02 | H18: =G18*IFERROR(INDEX('Item Master'!$E$4:$E$41,MATCH(D18,'Item Master'!$A$4:$A$41,0)),INDEX('Sub-Recipe'!$K$4:$K$200,MATCH(D18,'Sub-Recipe'!$A$4:$A$200,0))) -> 0.8 | I18: =IFERROR(INDEX('Daily Sales'!$AK$5:$AK$30,MATCH($B18,'Daily Sales'!$A$5:$A$30,0)),0) -> 41 | J18: =G18*I18 -> 0.82
A19: RC-FM002 | B19: FM002 | C19: Double Beef Burger | D19: FD007 | E19: Cheddar Cheese Slice | F19: Pcs | G19: 2 | H19: =G19*IFERROR(INDEX('Item Master'!$E$4:$E$41,MATCH(D19,'Item Master'!$A$4:$A$41,0)),INDEX('Sub-Recipe'!$K$4:$K$200,MATCH(D19,'Sub-Recipe'!$A$4:$A$200,0))) -> 24 | I19: =IFERROR(INDEX('Daily Sales'!$AK$5:$AK$30,MATCH($B19,'Daily Sales'!$A$5:$A$30,0)),0) -> 41 | J19: =G19*I19 -> 82
A20: RC-FM002 | B20: FM002 | C20: Double Beef Burger | D20: FD013 | E20: Mayonnaise | F20: Kg | G20: 0.02 | H20: =G20*IFERROR(INDEX('Item Master'!$E$4:$E$41,MATCH(D20,'Item Master'!$A$4:$A$41,0)),INDEX('Sub-Recipe'!$K$4:$K$200,MATCH(D20,'Sub-Recipe'!$A$4:$A$200,0))) -> 4.4 | I20: =IFERROR(INDEX('Daily Sales'!$AK$5:$AK$30,MATCH($B20,'Daily Sales'!$A$5:$A$30,0)),0) -> 41 | J20: =G20*I20 -> 0.82
A21: RC-FM002 | B21: FM002 | C21: Double Beef Burger | D21: FD014 | E21: Tomato Ketchup | F21: Kg | G21: 0.02 | H21: =G21*IFERROR(INDEX('Item Master'!$E$4:$E$41,MATCH(D21,'Item Master'!$A$4:$A$41,0)),INDEX('Sub-Recipe'!$K$4:$K$200,MATCH(D21,'Sub-Recipe'!$A$4:$A$200,0))) -> 3.6 | I21: =IFERROR(INDEX('Daily Sales'!$AK$5:$AK$30,MATCH($B21,'Daily Sales'!$A$5:$A$30,0)),0) -> 41 | J21: =G21*I21 -> 0.82
A22: RC-FM002 | B22: FM002 | C22: TOTAL STANDARD RECIPE COST - Double Beef Burger | D22: TOTAL | H22: =SUM(H14:H21) -> 200.65
A24: RC-FM003 | B24: FM003 | C24: Chicken Caesar Wrap | D24: FD002 | E24: Chicken Breast (Boneless) | F24: Kg | G24: 0.15 | H24: =G24*IFERROR(INDEX('Item Master'!$E$4:$E$41,MATCH(D24,'Item Master'!$A$4:$A$41,0)),INDEX('Sub-Recipe'!$K$4:$K$200,MATCH(D24,'Sub-Recipe'!$A$4:$A$200,0))) -> 72 | I24: =IFERROR(INDEX('Daily Sales'!$AK$5:$AK$30,MATCH($B24,'Daily Sales'!$A$5:$A$30,0)),0) -> 51 | J24: =G24*I24 -> 7.65
A25: RC-FM003 | B25: FM003 | C25: Chicken Caesar Wrap | D25: FD012 | E25: Tortilla Wrap | F25: Pcs | G25: 1 | H25: =G25*IFERROR(INDEX('Item Master'!$E$4:$E$41,MATCH(D25,'Item Master'!$A$4:$A$41,0)),INDEX('Sub-Recipe'!$K$4:$K$200,MATCH(D25,'Sub-Recipe'!$A$4:$A$200,0))) -> 15 | I25: =IFERROR(INDEX('Daily Sales'!$AK$5:$AK$30,MATCH($B25,'Daily Sales'!$A$5:$A$30,0)),0) -> 51 | J25: =G25*I25 -> 51
A26: RC-FM003 | B26: FM003 | C26: Chicken Caesar Wrap | D26: FD004 | E26: Fresh Lettuce | F26: Kg | G26: 0.03 | H26: =G26*IFERROR(INDEX('Item Master'!$E$4:$E$41,MATCH(D26,'Item Master'!$A$4:$A$41,0)),INDEX('Sub-Recipe'!$K$4:$K$200,MATCH(D26,'Sub-Recipe'!$A$4:$A$200,0))) -> 1.8 | I26: =IFERROR(INDEX('Daily Sales'!$AK$5:$AK$30,MATCH($B26,'Daily Sales'!$A$5:$A$30,0)),0) -> 51 | J26: =G26*I26 -> 1.53
A27: RC-FM003 | B27: FM003 | C27: Chicken Caesar Wrap | D27: SR008 | E27: TOTAL - Caesar Dressing (Homemade) (Sub-Recipe) | F27: Portions (100g) | G27: 1 | H27: =G27*IFERROR(INDEX('Item Master'!$E$4:$E$41,MATCH(D27,'Item Master'!$A$4:$A$41,0)),INDEX('Sub-Recipe'!$K$4:$K$200,MATCH(D27,'Sub-Recipe'!$A$4:$A$200,0))) -> 0 | I27: =IFERROR(INDEX('Daily Sales'!$AK$5:$AK$30,MATCH($B27,'Daily Sales'!$A$5:$A$30,0)),0) -> 51 | J27: =G27*I27 -> 51
A28: RC-FM003 | B28: FM003 | C28: Chicken Caesar Wrap | D28: FD015 | E28: Mozzarella Cheese | F28: Kg | G28: 0.03 | H28: =G28*IFERROR(INDEX('Item Master'!$E$4:$E$41,MATCH(D28,'Item Master'!$A$4:$A$41,0)),INDEX('Sub-Recipe'!$K$4:$K$200,MATCH(D28,'Sub-Recipe'!$A$4:$A$200,0))) -> 18.6 | I28: =IFERROR(INDEX('Daily Sales'!$AK$5:$AK$30,MATCH($B28,'Daily Sales'!$A$5:$A$30,0)),0) -> 51 | J28: =G28*I28 -> 1.53
A29: RC-FM003 | B29: FM003 | C29: TOTAL STANDARD RECIPE COST - Chicken Caesar Wrap | D29: TOTAL | H29: =SUM(H24:H28) -> 107.4
A31: RC-FM004 | B31: FM004 | C31: Crispy Chicken Wrap | D31: FD002 | E31: Chicken Breast (Boneless) | F31: Kg | G31: 0.15 | H31: =G31*IFERROR(INDEX('Item Master'!$E$4:$E$41,MATCH(D31,'Item Master'!$A$4:$A$41,0)),INDEX('Sub-Recipe'!$K$4:$K$200,MATCH(D31,'Sub-Recipe'!$A$4:$A$200,0))) -> 72 | I31: =IFERROR(INDEX('Daily Sales'!$AK$5:$AK$30,MATCH($B31,'Daily Sales'!$A$5:$A$30,0)),0) -> 58 | J31: =G31*I31 -> 8.7
A32: RC-FM004 | B32: FM004 | C32: Crispy Chicken Wrap | D32: FD012 | E32: Tortilla Wrap | F32: Pcs | G32: 1 | H32: =G32*IFERROR(INDEX('Item Master'!$E$4:$E$41,MATCH(D32,'Item Master'!$A$4:$A$41,0)),INDEX('Sub-Recipe'!$K$4:$K$200,MATCH(D32,'Sub-Recipe'!$A$4:$A$200,0))) -> 15 | I32: =IFERROR(INDEX('Daily Sales'!$AK$5:$AK$30,MATCH($B32,'Daily Sales'!$A$5:$A$30,0)),0) -> 58 | J32: =G32*I32 -> 58
A33: RC-FM004 | B33: FM004 | C33: Crispy Chicken Wrap | D33: FD004 | E33: Fresh Lettuce | F33: Kg | G33: 0.03 | H33: =G33*IFERROR(INDEX('Item Master'!$E$4:$E$41,MATCH(D33,'Item Master'!$A$4:$A$41,0)),INDEX('Sub-Recipe'!$K$4:$K$200,MATCH(D33,'Sub-Recipe'!$A$4:$A$200,0))) -> 1.8 | I33: =IFERROR(INDEX('Daily Sales'!$AK$5:$AK$30,MATCH($B33,'Daily Sales'!$A$5:$A$30,0)),0) -> 58 | J33: =G33*I33 -> 1.74
A34: RC-FM004 | B34: FM004 | C34: Crispy Chicken Wrap | D34: FD013 | E34: Mayonnaise | F34: Kg | G34: 0.03 | H34: =G34*IFERROR(INDEX('Item Master'!$E$4:$E$41,MATCH(D34,'Item Master'!$A$4:$A$41,0)),INDEX('Sub-Recipe'!$K$4:$K$200,MATCH(D34,'Sub-Recipe'!$A$4:$A$200,0))) -> 6.6 | I34: =IFERROR(INDEX('Daily Sales'!$AK$5:$AK$30,MATCH($B34,'Daily Sales'!$A$5:$A$30,0)),0) -> 58 | J34: =G34*I34 -> 1.74
A35: RC-FM004 | B35: FM004 | C35: Crispy Chicken Wrap | D35: FD006 | E35: Onion | F35: Kg | G35: 0.02 | H35: =G35*IFERROR(INDEX('Item Master'!$E$4:$E$41,MATCH(D35,'Item Master'!$A$4:$A$41,0)),INDEX('Sub-Recipe'!$K$4:$K$200,MATCH(D35,'Sub-Recipe'!$A$4:$A$200,0))) -> 0.8 | I35: =IFERROR(INDEX('Daily Sales'!$AK$5:$AK$30,MATCH($B35,'Daily Sales'!$A$5:$A$30,0)),0) -> 58 | J35: =G35*I35 -> 1.16
A36: RC-FM004 | B36: FM004 | C36: Crispy Chicken Wrap | D36: OT007 | E36: Cooking / Vegetable Oil | F36: Ltr | G36: 0.05 | H36: =G36*IFERROR(INDEX('Item Master'!$E$4:$E$41,MATCH(D36,'Item Master'!$A$4:$A$41,0)),INDEX('Sub-Recipe'!$K$4:$K$200,MATCH(D36,'Sub-Recipe'!$A$4:$A$200,0))) -> 7.5 | I36: =IFERROR(INDEX('Daily Sales'!$AK$5:$AK$30,MATCH($B36,'Daily Sales'!$A$5:$A$30,0)),0) -> 58 | J36: =G36*I36 -> 2.9
A37: RC-FM004 | B37: FM004 | C37: TOTAL STANDARD RECIPE COST - Crispy Chicken Wrap | D37: TOTAL | H37: =SUM(H31:H36) -> 103.7
A39: RC-FM005 | B39: FM005 | C39: Club Sandwich | D39: SR002 | E39: TOTAL - Sandwich Bread Loaf (Homemade) (Sub-Recipe) | F39: Slices | G39: 3 | H39: =G39*IFERROR(INDEX('Item Master'!$E$4:$E$41,MATCH(D39,'Item Master'!$A$4:$A$41,0)),INDEX('Sub-Recipe'!$K$4:$K$200,MATCH(D39,'Sub-Recipe'!$A$4:$A$200,0))) -> 0 | I39: =IFERROR(INDEX('Daily Sales'!$AK$5:$AK$30,MATCH($B39,'Daily Sales'!$A$5:$A$30,0)),0) -> 50 | J39: =G39*I39 -> 150
A40: RC-FM005 | B40: FM005 | C40: Club Sandwich | D40: FD002 | E40: Chicken Breast (Boneless) | F40: Kg | G40: 0.1 | H40: =G40*IFERROR(INDEX('Item Master'!$E$4:$E$41,MATCH(D40,'Item Master'!$A$4:$A$41,0)),INDEX('Sub-Recipe'!$K$4:$K$200,MATCH(D40,'Sub-Recipe'!$A$4:$A$200,0))) -> 48 | I40: =IFERROR(INDEX('Daily Sales'!$AK$5:$AK$30,MATCH($B40,'Daily Sales'!$A$5:$A$30,0)),0) -> 50 | J40: =G40*I40 -> 5
A41: RC-FM005 | B41: FM005 | C41: Club Sandwich | D41: FD003 | E41: Bacon Strips | F41: Kg | G41: 0.05 | H41: =G41*IFERROR(INDEX('Item Master'!$E$4:$E$41,MATCH(D41,'Item Master'!$A$4:$A$41,0)),INDEX('Sub-Recipe'!$K$4:$K$200,MATCH(D41,'Sub-Recipe'!$A$4:$A$200,0))) -> 32.5 | I41: =IFERROR(INDEX('Daily Sales'!$AK$5:$AK$30,MATCH($B41,'Daily Sales'!$A$5:$A$30,0)),0) -> 50 | J41: =G41*I41 -> 2.5
A42: RC-FM005 | B42: FM005 | C42: Club Sandwich | D42: FD004 | E42: Fresh Lettuce | F42: Kg | G42: 0.02 | H42: =G42*IFERROR(INDEX('Item Master'!$E$4:$E$41,MATCH(D42,'Item Master'!$A$4:$A$41,0)),INDEX('Sub-Recipe'!$K$4:$K$200,MATCH(D42,'Sub-Recipe'!$A$4:$A$200,0))) -> 1.2 | I42: =IFERROR(INDEX('Daily Sales'!$AK$5:$AK$30,MATCH($B42,'Daily Sales'!$A$5:$A$30,0)),0) -> 50 | J42: =G42*I42 -> 1
A43: RC-FM005 | B43: FM005 | C43: Club Sandwich | D43: FD005 | E43: Fresh Tomato | F43: Kg | G43: 0.03 | H43: =G43*IFERROR(INDEX('Item Master'!$E$4:$E$41,MATCH(D43,'Item Master'!$A$4:$A$41,0)),INDEX('Sub-Recipe'!$K$4:$K$200,MATCH(D43,'Sub-Recipe'!$A$4:$A$200,0))) -> 1.65 | I43: =IFERROR(INDEX('Daily Sales'!$AK$5:$AK$30,MATCH($B43,'Daily Sales'!$A$5:$A$30,0)),0) -> 50 | J43: =G43*I43 -> 1.5
A44: RC-FM005 | B44: FM005 | C44: Club Sandwich | D44: FD007 | E44: Cheddar Cheese Slice | F44: Pcs | G44: 1 | H44: =G44*IFERROR(INDEX('Item Master'!$E$4:$E$41,MATCH(D44,'Item Master'!$A$4:$A$41,0)),INDEX('Sub-Recipe'!$K$4:$K$200,MATCH(D44,'Sub-Recipe'!$A$4:$A$200,0))) -> 12 | I44: =IFERROR(INDEX('Daily Sales'!$AK$5:$AK$30,MATCH($B44,'Daily Sales'!$A$5:$A$30,0)),0) -> 50 | J44: =G44*I44 -> 50
...

Sheet Sub-Recipe
A1: SUB-RECIPE MASTER
A2: Homemade components costed once, then pulled into Recipe Master as a single ingredient line
A3: SUB-RECIPE CODE | B3: MENU CODE(S) | C3: COMPONENT NAME | D3: ITEM CODE | E3: INGREDIENT | F3: UOM | G3: QTY | H3: ITEM COST (ETB) | I3: BATCH YIELD QTY | J3: YIELD UOM | K3: COST PER UNIT (ETB) | L3: PORTIONS CONSUMED (MONTHLY) | M3: BATCHES REQUIRED | N3: THEORETICAL RAW QTY THIS LINE
A4: SR001 | B4: FM001, FM002 | C4: Burger Bun (Homemade) | D4: FD008 | E4: All-Purpose Flour | F4: Kg | G4: 1 | H4: =G4*IFERROR(INDEX('Item Master'!$E$4:$E$41,MATCH(D4,'Item Master'!$A$4:$A$41,0)),0) -> 55 | N4: =G4*$M$10 -> 6.6
A5: SR001 | B5: FM001, FM002 | C5: Burger Bun (Homemade) | D5: OT008 | E5: Instant Dry Yeast | F5: Kg | G5: 0.02 | H5: =G5*IFERROR(INDEX('Item Master'!$E$4:$E$41,MATCH(D5,'Item Master'!$A$4:$A$41,0)),0) -> 8 | N5: =G5*$M$10 -> 0.132
A6: SR001 | B6: FM001, FM002 | C6: Burger Bun (Homemade) | D6: FD009 | E6: Butter (Unsalted) | F6: Kg | G6: 0.08 | H6: =G6*IFERROR(INDEX('Item Master'!$E$4:$E$41,MATCH(D6,'Item Master'!$A$4:$A$41,0)),0) -> 38.4 | N6: =G6*$M$10 -> 0.528
A7: SR001 | B7: FM001, FM002 | C7: Burger Bun (Homemade) | D7: OT005 | E7: White Sugar | F7: Kg | G7: 0.05 | H7: =G7*IFERROR(INDEX('Item Master'!$E$4:$E$41,MATCH(D7,'Item Master'!$A$4:$A$41,0)),0) -> 3 | N7: =G7*$M$10 -> 0.33
A8: SR001 | B8: FM001, FM002 | C8: Burger Bun (Homemade) | D8: OT006 | E8: Iodized Salt | F8: Kg | G8: 0.015 | H8: =G8*IFERROR(INDEX('Item Master'!$E$4:$E$41,MATCH(D8,'Item Master'!$A$4:$A$41,0)),0) -> 0.375 | N8: =G8*$M$10 -> 0.099
A9: SR001 | B9: FM001, FM002 | C9: Burger Bun (Homemade) | D9: FD010 | E9: Fresh Eggs | F9: Pcs | G9: 1 | H9: =G9*IFERROR(INDEX('Item Master'!$E$4:$E$41,MATCH(D9,'Item Master'!$A$4:$A$41,0)),0) -> 8 | N9: =G9*$M$10 -> 6.6
A10: SR001 | C10: TOTAL - Burger Bun (Homemade) | D10: TOTAL | H10: =SUM(H4:H9) -> 112.775 | I10: 20 | J10: Pcs | K10: =IFERROR(H10/I10,0) -> 5.63875 | L10: =SUMIF('Recipe Master'!$D$4:$D$146,A10,'Recipe Master'!$J$4:$J$146) -> 132 | M10: =IFERROR(L10/I10,0) -> 6.6
A12: SR002 | B12: FM005, FM006, FM009 | C12: Sandwich Bread Loaf (Homemade) | D12: FD008 | E12: All-Purpose Flour | F12: Kg | G12: 1 | H12: =G12*IFERROR(INDEX('Item Master'!$E$4:$E$41,MATCH(D12,'Item Master'!$A$4:$A$41,0)),0) -> 55 | N12: =G12*$M$17 -> 16.4
A13: SR002 | B13: FM005, FM006, FM009 | C13: Sandwich Bread Loaf (Homemade) | D13: OT008 | E13: Instant Dry Yeast | F13: Kg | G13: 0.02 | H13: =G13*IFERROR(INDEX('Item Master'!$E$4:$E$41,MATCH(D13,'Item Master'!$A$4:$A$41,0)),0) -> 8 | N13: =G13*$M$17 -> 0.328
A14: SR002 | B14: FM005, FM006, FM009 | C14: Sandwich Bread Loaf (Homemade) | D14: FD009 | E14: Butter (Unsalted) | F14: Kg | G14: 0.05 | H14: =G14*IFERROR(INDEX('Item Master'!$E$4:$E$41,MATCH(D14,'Item Master'!$A$4:$A$41,0)),0) -> 24 | N14: =G14*$M$17 -> 0.82
A15: SR002 | B15: FM005, FM006, FM009 | C15: Sandwich Bread Loaf (Homemade) | D15: OT006 | E15: Iodized Salt | F15: Kg | G15: 0.015 | H15: =G15*IFERROR(INDEX('Item Master'!$E$4:$E$41,MATCH(D15,'Item Master'!$A$4:$A$41,0)),0) -> 0.375 | N15: =G15*$M$17 -> 0.246
A16: SR002 | B16: FM005, FM006, FM009 | C16: Sandwich Bread Loaf (Homemade) | D16: OT005 | E16: White Sugar | F16: Kg | G16: 0.02 | H16: =G16*IFERROR(INDEX('Item Master'!$E$4:$E$41,MATCH(D16,'Item Master'!$A$4:$A$41,0)),0) -> 1.2 | N16: =G16*$M$17 -> 0.328
A17: SR002 | C17: TOTAL - Sandwich Bread Loaf (Homemade) | D17: TOTAL | H17: =SUM(H12:H16) -> 88.575 | I17: 20 | J17: Slices | K17: =IFERROR(H17/I17,0) -> 4.42875 | L17: =SUMIF('Recipe Master'!$D$4:$D$146,A17,'Recipe Master'!$J$4:$J$146) -> 328 | M17: =IFERROR(L17/I17,0) -> 16.4
A19: SR003 | B19: FM010, FM011 | C19: Croissant Dough (Homemade) | D19: FD008 | E19: All-Purpose Flour | F19: Kg | G19: 1 | H19: =G19*IFERROR(INDEX('Item Master'!$E$4:$E$41,MATCH(D19,'Item Master'!$A$4:$A$41,0)),0) -> 55 | N19: =G19*$M$24 -> 11.2
A20: SR003 | B20: FM010, FM011 | C20: Croissant Dough (Homemade) | D20: FD009 | E20: Butter (Unsalted) | F20: Kg | G20: 0.5 | H20: =G20*IFERROR(INDEX('Item Master'!$E$4:$E$41,MATCH(D20,'Item Master'!$A$4:$A$41,0)),0) -> 240 | N20: =G20*$M$24 -> 5.6
A21: SR003 | B21: FM010, FM011 | C21: Croissant Dough (Homemade) | D21: OT005 | E21: White Sugar | F21: Kg | G21: 0.05 | H21: =G21*IFERROR(INDEX('Item Master'!$E$4:$E$41,MATCH(D21,'Item Master'!$A$4:$A$41,0)),0) -> 3 | N21: =G21*$M$24 -> 0.56
A22: SR003 | B22: FM010, FM011 | C22: Croissant Dough (Homemade) | D22: OT008 | E22: Instant Dry Yeast | F22: Kg | G22: 0.02 | H22: =G22*IFERROR(INDEX('Item Master'!$E$4:$E$41,MATCH(D22,'Item Master'!$A$4:$A$41,0)),0) -> 8 | N22: =G22*$M$24 -> 0.224
A23: SR003 | B23: FM010, FM011 | C23: Croissant Dough (Homemade) | D23: FD010 | E23: Fresh Eggs | F23: Pcs | G23: 1 | H23: =G23*IFERROR(INDEX('Item Master'!$E$4:$E$41,MATCH(D23,'Item Master'!$A$4:$A$41,0)),0) -> 8 | N23: =G23*$M$24 -> 11.2
A24: SR003 | C24: TOTAL - Croissant Dough (Homemade) | D24: TOTAL | H24: =SUM(H19:H23) -> 314 | I24: 10 | J24: Pcs | K24: =IFERROR(H24/I24,0) -> 31.4 | L24: =SUMIF('Recipe Master'!$D$4:$D$146,A24,'Recipe Master'!$J$4:$J$146) -> 112 | M24: =IFERROR(L24/I24,0) -> 11.2
A26: SR004 | B26: FM010, FM012 | C26: Danish Pastry Dough (Homemade) | D26: FD008 | E26: All-Purpose Flour | F26: Kg | G26: 1 | H26: =G26*IFERROR(INDEX('Item Master'!$E$4:$E$41,MATCH(D26,'Item Master'!$A$4:$A$41,0)),0) -> 55 | N26: =G26*$M$30 -> 8.9
A27: SR004 | B27: FM010, FM012 | C27: Danish Pastry Dough (Homemade) | D27: FD009 | E27: Butter (Unsalted) | F27: Kg | G27: 0.4 | H27: =G27*IFERROR(INDEX('Item Master'!$E$4:$E$41,MATCH(D27,'Item Master'!$A$4:$A$41,0)),0) -> 192 | N27: =G27*$M$30 -> 3.56
A28: SR004 | B28: FM010, FM012 | C28: Danish Pastry Dough (Homemade) | D28: OT005 | E28: White Sugar | F28: Kg | G28: 0.1 | H28: =G28*IFERROR(INDEX('Item Master'!$E$4:$E$41,MATCH(D28,'Item Master'!$A$4:$A$41,0)),0) -> 6 | N28: =G28*$M$30 -> 0.89
A29: SR004 | B29: FM010, FM012 | C29: Danish Pastry Dough (Homemade) | D29: FD010 | E29: Fresh Eggs | F29: Pcs | G29: 2 | H29: =G29*IFERROR(INDEX('Item Master'!$E$4:$E$41,MATCH(D29,'Item Master'!$A$4:$A$41,0)),0) -> 16 | N29: =G29*$M$30 -> 17.8
A30: SR004 | C30: TOTAL - Danish Pastry Dough (Homemade) | D30: TOTAL | H30: =SUM(H26:H29) -> 269 | I30: 10 | J30: Pcs | K30: =IFERROR(H30/I30,0) -> 26.9 | L30: =SUMIF('Recipe Master'!$D$4:$D$146,A30,'Recipe Master'!$J$4:$J$146) -> 89 | M30: =IFERROR(L30/I30,0) -> 8.9
A32: SR005 | B32: FM015 | C32: Pizza Dough Base (Homemade) | D32: FD008 | E32: All-Purpose Flour | F32: Kg | G32: 1 | H32: =G32*IFERROR(INDEX('Item Master'!$E$4:$E$41,MATCH(D32,'Item Master'!$A$4:$A$41,0)),0) -> 55 | N32: =G32*$M$36 -> 16.4
A33: SR005 | B33: FM015 | C33: Pizza Dough Base (Homemade) | D33: OT008 | E33: Instant Dry Yeast | F33: Kg | G33: 0.02 | H33: =G33*IFERROR(INDEX('Item Master'!$E$4:$E$41,MATCH(D33,'Item Master'!$A$4:$A$41,0)),0) -> 8 | N33: =G33*$M$36 -> 0.328
A34: SR005 | B34: FM015 | C34: Pizza Dough Base (Homemade) | D34: OT006 | E34: Iodized Salt | F34: Kg | G34: 0.02 | H34: =G34*IFERROR(INDEX('Item Master'!$E$4:$E$41,MATCH(D34,'Item Master'!$A$4:$A$41,0)),0) -> 0.5 | N34: =G34*$M$36 -> 0.328
A35: SR005 | B35: FM015 | C35: Pizza Dough Base (Homemade) | D35: OT007 | E35: Cooking / Vegetable Oil | F35: Ltr | G35: 0.05 | H35: =G35*IFERROR(INDEX('Item Master'!$E$4:$E$41,MATCH(D35,'Item Master'!$A$4:$A$41,0)),0) -> 7.5 | N35: =G35*$M$36 -> 0.82
A36: SR005 | C36: TOTAL - Pizza Dough Base (Homemade) | D36: TOTAL | H36: =SUM(H32:H35) -> 71 | I36: 5 | J36: Bases | K36: =IFERROR(H36/I36,0) -> 14.2 | L36: =SUMIF('Recipe Master'!$D$4:$D$146,A36,'Recipe Master'!$J$4:$J$146) -> 82 | M36: =IFERROR(L36/I36,0) -> 16.4
A38: SR006 | B38: FM007 | C38: Bolognese Sauce (Homemade) | D38: FD001 | E38: Beef Mince (80% Lean) | F38: Kg | G38: 1 | H38: =G38*IFERROR(INDEX('Item Master'!$E$4:$E$41,MATCH(D38,'Item Master'!$A$4:$A$41,0)),0) -> 550 | N38: =G38*$M$43 -> 8.25
A39: SR006 | B39: FM007 | C39: Bolognese Sauce (Homemade) | D39: FD005 | E39: Fresh Tomato | F39: Kg | G39: 0.5 | H39: =G39*IFERROR(INDEX('Item Master'!$E$4:$E$41,MATCH(D39,'Item Master'!$A$4:$A$41,0)),0) -> 27.5 | N39: =G39*$M$43 -> 4.125
A40: SR006 | B40: FM007 | C40: Bolognese Sauce (Homemade) | D40: FD006 | E40: Onion | F40: Kg | G40: 0.3 | H40: =G40*IFERROR(INDEX('Item Master'!$E$4:$E$41,MATCH(D40,'Item Master'!$A$4:$A$41,0)),0) -> 12 | N40: =G40*$M$43 -> 2.475
A41: SR006 | B41: FM007 | C41: Bolognese Sauce (Homemade) | D41: OT007 | E41: Cooking / Vegetable Oil | F41: Ltr | G41: 0.05 | H41: =G41*IFERROR(INDEX('Item Master'!$E$4:$E$41,MATCH(D41,'Item Master'!$A$4:$A$41,0)),0) -> 7.5 | N41: =G41*$M$43 -> 0.4125
A42: SR006 | B42: FM007 | C42: Bolognese Sauce (Homemade) | D42: OT006 | E42: Iodized Salt | F42: Kg | G42: 0.02 | H42: =G42*IFERROR(INDEX('Item Master'!$E$4:$E$41,MATCH(D42,'Item Master'!$A$4:$A$41,0)),0) -> 0.5 | N42: =G42*$M$43 -> 0.165
A43: SR006 | C43: TOTAL - Bolognese Sauce (Homemade) | D43: TOTAL | H43: =SUM(H38:H42) -> 597.5 | I43: 8 | J43: Portions (250g) | K43: =IFERROR(H43/I43,0) -> 74.6875 | L43: =SUMIF('Recipe Master'!$D$4:$D$146,A43,'Recipe Master'!$J$4:$J$146) -> 66 | M43: =IFERROR(L43/I43,0) -> 8.25
A45: SR007 | B45: FM008 | C45: Alfredo Sauce (Homemade) | D45: FD009 | E45: Butter (Unsalted) | F45: Kg | G45: 0.3 | H45: =G45*IFERROR(INDEX('Item Master'!$E$4:$E$41,MATCH(D45,'Item Master'!$A$4:$A$41,0)),0) -> 144 | N45: =G45*$M$49 -> 1.8
A46: SR007 | B46: FM008 | C46: Alfredo Sauce (Homemade) | D46: BV004 | E46: Fresh Milk | F46: Ltr | G46: 0.5 | H46: =G46*IFERROR(INDEX('Item Master'!$E$4:$E$41,MATCH(D46,'Item Master'!$A$4:$A$41,0)),0) -> 32.5 | N46: =G46*$M$49 -> 3
...

Sheet Purchase Register
A1: PURCHASE REGISTER
A2: What was bought, from whom, at what cost — feeds the Main Store
A3: Enter each purchase event's date in row 3 above its Qty/Cost/Total block. | F3: 46206 | I3: 46218 | L3: Insert Date | O3: Insert Date | R3: Insert Date | U3: Insert Date | X3: Insert Date | AA3: Insert Date | AD3: Insert Date
A4: ITEM CODE | B4: ITEM NAME | C4: CATEGORY | D4: UOM | E4: OPENING AVG. COST | F4: P1 Qty | G4: P1 Cost | H4: P1 Total | I4: P2 Qty | J4: P2 Cost | K4: P2 Total | L4: P3 Qty | M4: P3 Cost | N4: P3 Total | O4: P4 Qty | P4: P4 Cost | Q4: P4 Total | R4: P5 Qty | S4: P5 Cost | T4: P5 Total | U4: P6 Qty | V4: P6 Cost | W4: P6 Total | X4: P7 Qty | Y4: P7 Cost | Z4: P7 Total | AA4: P8 Qty | AB4: P8 Cost | AC4: P8 Total | AD4: P9 Qty | AE4: P9 Cost | AF4: P9 Total | AG4: TOTAL QTY | AH4: TOTAL COST | AI4: AVG. COST
A5: FOOD
A6: FD001 | B6: Beef Mince (80% Lean) | C6: Meat & Poultry | D6: Kg | E6: ='Item Master'!E5 -> 550 | F6: 45 | G6: 555 | H6: =IFERROR(F6*G6,0) -> 24975 | I6: 40 | J6: 560 | K6: =IFERROR(I6*J6,0) -> 22400 | N6: =IFERROR(L6*M6,0) -> 0 | Q6: =IFERROR(O6*P6,0) -> 0 | T6: =IFERROR(R6*S6,0) -> 0 | W6: =IFERROR(U6*V6,0) -> 0 | Z6: =IFERROR(X6*Y6,0) -> 0 | AC6: =IFERROR(AA6*AB6,0) -> 0 | AF6: =IFERROR(AD6*AE6,0) -> 0 | AG6: =F6+I6+L6+O6+R6+U6+X6+AA6+AD6 -> 85 | AH6: =H6+K6+N6+Q6+T6+W6+Z6+AC6+AF6 -> 47375 | AI6: =IFERROR(AH6/AG6,E6) -> 557.35294
A7: FD002 | B7: Chicken Breast (Boneless) | C7: Meat & Poultry | D7: Kg | E7: ='Item Master'!E6 -> 480 | F7: 40 | G7: 485 | H7: =IFERROR(F7*G7,0) -> 19400 | I7: 35 | J7: 480 | K7: =IFERROR(I7*J7,0) -> 16800 | N7: =IFERROR(L7*M7,0) -> 0 | Q7: =IFERROR(O7*P7,0) -> 0 | T7: =IFERROR(R7*S7,0) -> 0 | W7: =IFERROR(U7*V7,0) -> 0 | Z7: =IFERROR(X7*Y7,0) -> 0 | AC7: =IFERROR(AA7*AB7,0) -> 0 | AF7: =IFERROR(AD7*AE7,0) -> 0 | AG7: =F7+I7+L7+O7+R7+U7+X7+AA7+AD7 -> 75 | AH7: =H7+K7+N7+Q7+T7+W7+Z7+AC7+AF7 -> 36200 | AI7: =IFERROR(AH7/AG7,E7) -> 482.66667
A8: FD003 | B8: Bacon Strips | C8: Meat & Poultry | D8: Kg | E8: ='Item Master'!E7 -> 650 | F8: 20 | G8: 650 | H8: =IFERROR(F8*G8,0) -> 13000 | K8: =IFERROR(I8*J8,0) -> 0 | N8: =IFERROR(L8*M8,0) -> 0 | Q8: =IFERROR(O8*P8,0) -> 0 | T8: =IFERROR(R8*S8,0) -> 0 | W8: =IFERROR(U8*V8,0) -> 0 | Z8: =IFERROR(X8*Y8,0) -> 0 | AC8: =IFERROR(AA8*AB8,0) -> 0 | AF8: =IFERROR(AD8*AE8,0) -> 0 | AG8: =F8+I8+L8+O8+R8+U8+X8+AA8+AD8 -> 20 | AH8: =H8+K8+N8+Q8+T8+W8+Z8+AC8+AF8 -> 13000 | AI8: =IFERROR(AH8/AG8,E8) -> 650
A9: FD004 | B9: Fresh Lettuce | C9: Fresh Produce | D9: Kg | E9: ='Item Master'!E8 -> 60 | F9: 25 | G9: 58 | H9: =IFERROR(F9*G9,0) -> 1450 | I9: 25 | J9: 62 | K9: =IFERROR(I9*J9,0) -> 1550 | N9: =IFERROR(L9*M9,0) -> 0 | Q9: =IFERROR(O9*P9,0) -> 0 | T9: =IFERROR(R9*S9,0) -> 0 | W9: =IFERROR(U9*V9,0) -> 0 | Z9: =IFERROR(X9*Y9,0) -> 0 | AC9: =IFERROR(AA9*AB9,0) -> 0 | AF9: =IFERROR(AD9*AE9,0) -> 0 | AG9: =F9+I9+L9+O9+R9+U9+X9+AA9+AD9 -> 50 | AH9: =H9+K9+N9+Q9+T9+W9+Z9+AC9+AF9 -> 3000 | AI9: =IFERROR(AH9/AG9,E9) -> 60
A10: FD005 | B10: Fresh Tomato | C10: Fresh Produce | D10: Kg | E10: ='Item Master'!E9 -> 55 | F10: 25 | G10: 55 | H10: =IFERROR(F10*G10,0) -> 1375 | I10: 25 | J10: 57 | K10: =IFERROR(I10*J10,0) -> 1425 | N10: =IFERROR(L10*M10,0) -> 0 | Q10: =IFERROR(O10*P10,0) -> 0 | T10: =IFERROR(R10*S10,0) -> 0 | W10: =IFERROR(U10*V10,0) -> 0 | Z10: =IFERROR(X10*Y10,0) -> 0 | AC10: =IFERROR(AA10*AB10,0) -> 0 | AF10: =IFERROR(AD10*AE10,0) -> 0 | AG10: =F10+I10+L10+O10+R10+U10+X10+AA10+AD10 -> 50 | AH10: =H10+K10+N10+Q10+T10+W10+Z10+AC10+AF10 -> 2800 | AI10: =IFERROR(AH10/AG10,E10) -> 56
A11: FD006 | B11: Onion | C11: Fresh Produce | D11: Kg | E11: ='Item Master'!E10 -> 40 | F11: 25 | G11: 40 | H11: =IFERROR(F11*G11,0) -> 1000 | K11: =IFERROR(I11*J11,0) -> 0 | N11: =IFERROR(L11*M11,0) -> 0 | Q11: =IFERROR(O11*P11,0) -> 0 | T11: =IFERROR(R11*S11,0) -> 0 | W11: =IFERROR(U11*V11,0) -> 0 | Z11: =IFERROR(X11*Y11,0) -> 0 | AC11: =IFERROR(AA11*AB11,0) -> 0 | AF11: =IFERROR(AD11*AE11,0) -> 0 | AG11: =F11+I11+L11+O11+R11+U11+X11+AA11+AD11 -> 25 | AH11: =H11+K11+N11+Q11+T11+W11+Z11+AC11+AF11 -> 1000 | AI11: =IFERROR(AH11/AG11,E11) -> 40
A12: FD007 | B12: Cheddar Cheese Slice | C12: Dairy | D12: Pcs | E12: ='Item Master'!E11 -> 12 | F12: 150 | G12: 12 | H12: =IFERROR(F12*G12,0) -> 1800 | K12: =IFERROR(I12*J12,0) -> 0 | N12: =IFERROR(L12*M12,0) -> 0 | Q12: =IFERROR(O12*P12,0) -> 0 | T12: =IFERROR(R12*S12,0) -> 0 | W12: =IFERROR(U12*V12,0) -> 0 | Z12: =IFERROR(X12*Y12,0) -> 0 | AC12: =IFERROR(AA12*AB12,0) -> 0 | AF12: =IFERROR(AD12*AE12,0) -> 0 | AG12: =F12+I12+L12+O12+R12+U12+X12+AA12+AD12 -> 150 | AH12: =H12+K12+N12+Q12+T12+W12+Z12+AC12+AF12 -> 1800 | AI12: =IFERROR(AH12/AG12,E12) -> 12
A13: FD008 | B13: All-Purpose Flour | C13: Bakery & Dry Goods | D13: Kg | E13: ='Item Master'!E12 -> 55 | F13: 60 | G13: 55 | H13: =IFERROR(F13*G13,0) -> 3300 | K13: =IFERROR(I13*J13,0) -> 0 | N13: =IFERROR(L13*M13,0) -> 0 | Q13: =IFERROR(O13*P13,0) -> 0 | T13: =IFERROR(R13*S13,0) -> 0 | W13: =IFERROR(U13*V13,0) -> 0 | Z13: =IFERROR(X13*Y13,0) -> 0 | AC13: =IFERROR(AA13*AB13,0) -> 0 | AF13: =IFERROR(AD13*AE13,0) -> 0 | AG13: =F13+I13+L13+O13+R13+U13+X13+AA13+AD13 -> 60 | AH13: =H13+K13+N13+Q13+T13+W13+Z13+AC13+AF13 -> 3300 | AI13: =IFERROR(AH13/AG13,E13) -> 55
A14: FD009 | B14: Butter (Unsalted) | C14: Dairy | D14: Kg | E14: ='Item Master'!E13 -> 480 | F14: 20 | G14: 480 | H14: =IFERROR(F14*G14,0) -> 9600 | K14: =IFERROR(I14*J14,0) -> 0 | N14: =IFERROR(L14*M14,0) -> 0 | Q14: =IFERROR(O14*P14,0) -> 0 | T14: =IFERROR(R14*S14,0) -> 0 | W14: =IFERROR(U14*V14,0) -> 0 | Z14: =IFERROR(X14*Y14,0) -> 0 | AC14: =IFERROR(AA14*AB14,0) -> 0 | AF14: =IFERROR(AD14*AE14,0) -> 0 | AG14: =F14+I14+L14+O14+R14+U14+X14+AA14+AD14 -> 20 | AH14: =H14+K14+N14+Q14+T14+W14+Z14+AC14+AF14 -> 9600 | AI14: =IFERROR(AH14/AG14,E14) -> 480
A15: FD010 | B15: Fresh Eggs | C15: Dairy | D15: Pcs | E15: ='Item Master'!E14 -> 8 | F15: 150 | G15: 8 | H15: =IFERROR(F15*G15,0) -> 1200 | K15: =IFERROR(I15*J15,0) -> 0 | N15: =IFERROR(L15*M15,0) -> 0 | Q15: =IFERROR(O15*P15,0) -> 0 | T15: =IFERROR(R15*S15,0) -> 0 | W15: =IFERROR(U15*V15,0) -> 0 | Z15: =IFERROR(X15*Y15,0) -> 0 | AC15: =IFERROR(AA15*AB15,0) -> 0 | AF15: =IFERROR(AD15*AE15,0) -> 0 | AG15: =F15+I15+L15+O15+R15+U15+X15+AA15+AD15 -> 150 | AH15: =H15+K15+N15+Q15+T15+W15+Z15+AC15+AF15 -> 1200 | AI15: =IFERROR(AH15/AG15,E15) -> 8
A16: FD011 | B16: Spaghetti Pasta | C16: Bakery & Dry Goods | D16: Kg | E16: ='Item Master'!E15 -> 120 | F16: 35 | G16: 120 | H16: =IFERROR(F16*G16,0) -> 4200 | K16: =IFERROR(I16*J16,0) -> 0 | N16: =IFERROR(L16*M16,0) -> 0 | Q16: =IFERROR(O16*P16,0) -> 0 | T16: =IFERROR(R16*S16,0) -> 0 | W16: =IFERROR(U16*V16,0) -> 0 | Z16: =IFERROR(X16*Y16,0) -> 0 | AC16: =IFERROR(AA16*AB16,0) -> 0 | AF16: =IFERROR(AD16*AE16,0) -> 0 | AG16: =F16+I16+L16+O16+R16+U16+X16+AA16+AD16 -> 35 | AH16: =H16+K16+N16+Q16+T16+W16+Z16+AC16+AF16 -> 4200 | AI16: =IFERROR(AH16/AG16,E16) -> 120
A17: FD012 | B17: Tortilla Wrap | C17: Bakery & Dry Goods | D17: Pcs | E17: ='Item Master'!E16 -> 15 | F17: 90 | G17: 15 | H17: =IFERROR(F17*G17,0) -> 1350 | K17: =IFERROR(I17*J17,0) -> 0 | N17: =IFERROR(L17*M17,0) -> 0 | Q17: =IFERROR(O17*P17,0) -> 0 | T17: =IFERROR(R17*S17,0) -> 0 | W17: =IFERROR(U17*V17,0) -> 0 | Z17: =IFERROR(X17*Y17,0) -> 0 | AC17: =IFERROR(AA17*AB17,0) -> 0 | AF17: =IFERROR(AD17*AE17,0) -> 0 | AG17: =F17+I17+L17+O17+R17+U17+X17+AA17+AD17 -> 90 | AH17: =H17+K17+N17+Q17+T17+W17+Z17+AC17+AF17 -> 1350 | AI17: =IFERROR(AH17/AG17,E17) -> 15
A18: FD013 | B18: Mayonnaise | C18: Condiments & Sauces | D18: Kg | E18: ='Item Master'!E17 -> 220 | F18: 35 | G18: 220 | H18: =IFERROR(F18*G18,0) -> 7700 | K18: =IFERROR(I18*J18,0) -> 0 | N18: =IFERROR(L18*M18,0) -> 0 | Q18: =IFERROR(O18*P18,0) -> 0 | T18: =IFERROR(R18*S18,0) -> 0 | W18: =IFERROR(U18*V18,0) -> 0 | Z18: =IFERROR(X18*Y18,0) -> 0 | AC18: =IFERROR(AA18*AB18,0) -> 0 | AF18: =IFERROR(AD18*AE18,0) -> 0 | AG18: =F18+I18+L18+O18+R18+U18+X18+AA18+AD18 -> 35 | AH18: =H18+K18+N18+Q18+T18+W18+Z18+AC18+AF18 -> 7700 | AI18: =IFERROR(AH18/AG18,E18) -> 220
A19: FD014 | B19: Tomato Ketchup | C19: Condiments & Sauces | D19: Kg | E19: ='Item Master'!E18 -> 180 | F19: 35 | G19: 180 | H19: =IFERROR(F19*G19,0) -> 6300 | K19: =IFERROR(I19*J19,0) -> 0 | N19: =IFERROR(L19*M19,0) -> 0 | Q19: =IFERROR(O19*P19,0) -> 0 | T19: =IFERROR(R19*S19,0) -> 0 | W19: =IFERROR(U19*V19,0) -> 0 | Z19: =IFERROR(X19*Y19,0) -> 0 | AC19: =IFERROR(AA19*AB19,0) -> 0 | AF19: =IFERROR(AD19*AE19,0) -> 0 | AG19: =F19+I19+L19+O19+R19+U19+X19+AA19+AD19 -> 35 | AH19: =H19+K19+N19+Q19+T19+W19+Z19+AC19+AF19 -> 6300 | AI19: =IFERROR(AH19/AG19,E19) -> 180
A20: FD015 | B20: Mozzarella Cheese | C20: Dairy | D20: Kg | E20: ='Item Master'!E19 -> 620 | F20: 25 | G20: 620 | H20: =IFERROR(F20*G20,0) -> 15500 | K20: =IFERROR(I20*J20,0) -> 0 | N20: =IFERROR(L20*M20,0) -> 0 | Q20: =IFERROR(O20*P20,0) -> 0 | T20: =IFERROR(R20*S20,0) -> 0 | W20: =IFERROR(U20*V20,0) -> 0 | Z20: =IFERROR(X20*Y20,0) -> 0 | AC20: =IFERROR(AA20*AB20,0) -> 0 | AF20: =IFERROR(AD20*AE20,0) -> 0 | AG20: =F20+I20+L20+O20+R20+U20+X20+AA20+AD20 -> 25 | AH20: =H20+K20+N20+Q20+T20+W20+Z20+AC20+AF20 -> 15500 | AI20: =IFERROR(AH20/AG20,E20) -> 620
A21: BEVERAGE
A22: BV001 | B22: Coffee Beans (Roasted) | C22: Coffee & Tea | D22: Kg | E22: ='Item Master'!E21 -> 900 | F22: 25 | G22: 900 | H22: =IFERROR(F22*G22,0) -> 22500 | K22: =IFERROR(I22*J22,0) -> 0 | N22: =IFERROR(L22*M22,0) -> 0 | Q22: =IFERROR(O22*P22,0) -> 0 | T22: =IFERROR(R22*S22,0) -> 0 | W22: =IFERROR(U22*V22,0) -> 0 | Z22: =IFERROR(X22*Y22,0) -> 0 | AC22: =IFERROR(AA22*AB22,0) -> 0 | AF22: =IFERROR(AD22*AE22,0) -> 0 | AG22: =F22+I22+L22+O22+R22+U22+X22+AA22+AD22 -> 25 | AH22: =H22+K22+N22+Q22+T22+W22+Z22+AC22+AF22 -> 22500 | AI22: =IFERROR(AH22/AG22,E22) -> 900
A23: BV002 | B23: Black Tea Bags | C23: Coffee & Tea | D23: Pcs | E23: ='Item Master'!E22 -> 3 | H23: =IFERROR(F23*G23,0) -> 0 | K23: =IFERROR(I23*J23,0) -> 0 | N23: =IFERROR(L23*M23,0) -> 0 | Q23: =IFERROR(O23*P23,0) -> 0 | T23: =IFERROR(R23*S23,0) -> 0 | W23: =IFERROR(U23*V23,0) -> 0 | Z23: =IFERROR(X23*Y23,0) -> 0 | AC23: =IFERROR(AA23*AB23,0) -> 0 | AF23: =IFERROR(AD23*AE23,0) -> 0 | AG23: =F23+I23+L23+O23+R23+U23+X23+AA23+AD23 -> 0 | AH23: =H23+K23+N23+Q23+T23+W23+Z23+AC23+AF23 -> 0 | AI23: =IFERROR(AH23/AG23,E23) -> 3
A24: BV003 | B24: Green Tea Bags | C24: Coffee & Tea | D24: Pcs | E24: ='Item Master'!E23 -> 4 | H24: =IFERROR(F24*G24,0) -> 0 | K24: =IFERROR(I24*J24,0) -> 0 | N24: =IFERROR(L24*M24,0) -> 0 | Q24: =IFERROR(O24*P24,0) -> 0 | T24: =IFERROR(R24*S24,0) -> 0 | W24: =IFERROR(U24*V24,0) -> 0 | Z24: =IFERROR(X24*Y24,0) -> 0 | AC24: =IFERROR(AA24*AB24,0) -> 0 | AF24: =IFERROR(AD24*AE24,0) -> 0 | AG24: =F24+I24+L24+O24+R24+U24+X24+AA24+AD24 -> 0 | AH24: =H24+K24+N24+Q24+T24+W24+Z24+AC24+AF24 -> 0 | AI24: =IFERROR(AH24/AG24,E24) -> 4
A25: BV004 | B25: Fresh Milk | C25: Dairy & Bar | D25: Ltr | E25: ='Item Master'!E24 -> 65 | F25: 70 | G25: 65 | H25: =IFERROR(F25*G25,0) -> 4550 | I25: 60 | J25: 66 | K25: =IFERROR(I25*J25,0) -> 3960 | N25: =IFERROR(L25*M25,0) -> 0 | Q25: =IFERROR(O25*P25,0) -> 0 | T25: =IFERROR(R25*S25,0) -> 0 | W25: =IFERROR(U25*V25,0) -> 0 | Z25: =IFERROR(X25*Y25,0) -> 0 | AC25: =IFERROR(AA25*AB25,0) -> 0 | AF25: =IFERROR(AD25*AE25,0) -> 0 | AG25: =F25+I25+L25+O25+R25+U25+X25+AA25+AD25 -> 130 | AH25: =H25+K25+N25+Q25+T25+W25+Z25+AC25+AF25 -> 8510 | AI25: =IFERROR(AH25/AG25,E25) -> 65.461538
A26: BV005 | B26: Cocoa Powder | C26: Coffee & Tea | D26: Kg | E26: ='Item Master'!E25 -> 350 | H26: =IFERROR(F26*G26,0) -> 0 | K26: =IFERROR(I26*J26,0) -> 0 | N26: =IFERROR(L26*M26,0) -> 0 | Q26: =IFERROR(O26*P26,0) -> 0 | T26: =IFERROR(R26*S26,0) -> 0 | W26: =IFERROR(U26*V26,0) -> 0 | Z26: =IFERROR(X26*Y26,0) -> 0 | AC26: =IFERROR(AA26*AB26,0) -> 0 | AF26: =IFERROR(AD26*AE26,0) -> 0 | AG26: =F26+I26+L26+O26+R26+U26+X26+AA26+AD26 -> 0 | AH26: =H26+K26+N26+Q26+T26+W26+Z26+AC26+AF26 -> 0 | AI26: =IFERROR(AH26/AG26,E26) -> 350
A27: BV006 | B27: White Rum | C27: Bar & Spirits | D27: Ltr | E27: ='Item Master'!E26 -> 950 | F27: 12 | G27: 950 | H27: =IFERROR(F27*G27,0) -> 11400 | K27: =IFERROR(I27*J27,0) -> 0 | N27: =IFERROR(L27*M27,0) -> 0 | Q27: =IFERROR(O27*P27,0) -> 0 | T27: =IFERROR(R27*S27,0) -> 0 | W27: =IFERROR(U27*V27,0) -> 0 | Z27: =IFERROR(X27*Y27,0) -> 0 | AC27: =IFERROR(AA27*AB27,0) -> 0 | AF27: =IFERROR(AD27*AE27,0) -> 0 | AG27: =F27+I27+L27+O27+R27+U27+X27+AA27+AD27 -> 12 | AH27: =H27+K27+N27+Q27+T27+W27+Z27+AC27+AF27 -> 11400 | AI27: =IFERROR(AH27/AG27,E27) -> 950
A28: BV007 | B28: Fresh Mint Leaves | C28: Bar Garnish | D28: Kg | E28: ='Item Master'!E27 -> 150 | H28: =IFERROR(F28*G28,0) -> 0 | K28: =IFERROR(I28*J28,0) -> 0 | N28: =IFERROR(L28*M28,0) -> 0 | Q28: =IFERROR(O28*P28,0) -> 0 | T28: =IFERROR(R28*S28,0) -> 0 | W28: =IFERROR(U28*V28,0) -> 0 | Z28: =IFERROR(X28*Y28,0) -> 0 | AC28: =IFERROR(AA28*AB28,0) -> 0 | AF28: =IFERROR(AD28*AE28,0) -> 0 | AG28: =F28+I28+L28+O28+R28+U28+X28+AA28+AD28 -> 0 | AH28: =H28+K28+N28+Q28+T28+W28+Z28+AC28+AF28 -> 0 | AI28: =IFERROR(AH28/AG28,E28) -> 150
A29: BV008 | B29: Fresh Lime | C29: Bar Garnish | D29: Kg | E29: ='Item Master'!E28 -> 100 | F29: 12 | G29: 100 | H29: =IFERROR(F29*G29,0) -> 1200 | K29: =IFERROR(I29*J29,0) -> 0 | N29: =IFERROR(L29*M29,0) -> 0 | Q29: =IFERROR(O29*P29,0) -> 0 | T29: =IFERROR(R29*S29,0) -> 0 | W29: =IFERROR(U29*V29,0) -> 0 | Z29: =IFERROR(X29*Y29,0) -> 0 | AC29: =IFERROR(AA29*AB29,0) -> 0 | AF29: =IFERROR(AD29*AE29,0) -> 0 | AG29: =F29+I29+L29+O29+R29+U29+X29+AA29+AD29 -> 12 | AH29: =H29+K29+N29+Q29+T29+W29+Z29+AC29+AF29 -> 1200 | AI29: =IFERROR(AH29/AG29,E29) -> 100
A30: BV009 | B30: Fresh Avocado | C30: Fresh Produce | D30: Kg | E30: ='Item Master'!E29 -> 90 | F30: 20 | G30: 90 | H30: =IFERROR(F30*G30,0) -> 1800 | K30: =IFERROR(I30*J30,0) -> 0 | N30: =IFERROR(L30*M30,0) -> 0 | Q30: =IFERROR(O30*P30,0) -> 0 | T30: =IFERROR(R30*S30,0) -> 0 | W30: =IFERROR(U30*V30,0) -> 0 | Z30: =IFERROR(X30*Y30,0) -> 0 | AC30: =IFERROR(AA30*AB30,0) -> 0 | AF30: =IFERROR(AD30*AE30,0) -> 0 | AG30: =F30+I30+L30+O30+R30+U30+X30+AA30+AD30 -> 20 | AH30: =H30+K30+N30+Q30+T30+W30+Z30+AC30+AF30 -> 1800 | AI30: =IFERROR(AH30/AG30,E30) -> 90
A31: BV010 | B31: Soda Water | C31: Bar & Mixers | D31: Ltr | E31: ='Item Master'!E30 -> 45 | F31: 35 | G31: 45 | H31: =IFERROR(F31*G31,0) -> 1575 | K31: =IFERROR(I31*J31,0) -> 0 | N31: =IFERROR(L31*M31,0) -> 0 | Q31: =IFERROR(O31*P31,0) -> 0 | T31: =IFERROR(R31*S31,0) -> 0 | W31: =IFERROR(U31*V31,0) -> 0 | Z31: =IFERROR(X31*Y31,0) -> 0 | AC31: =IFERROR(AA31*AB31,0) -> 0 | AF31: =IFERROR(AD31*AE31,0) -> 0 | AG31: =F31+I31+L31+O31+R31+U31+X31+AA31+AD31 -> 35 | AH31: =H31+K31+N31+Q31+T31+W31+Z31+AC31+AF31 -> 1575 | AI31: =IFERROR(AH31/AG31,E31) -> 45
A32: BV011 | B32: Coca-Cola (330ml Bottle) | C32: Soft Drinks | D32: Bottle | E32: ='Item Master'!E31 -> 35 | F32: 220 | G32: 35 | H32: =IFERROR(F32*G32,0) -> 7700 | K32: =IFERROR(I32*J32,0) -> 0 | N32: =IFERROR(L32*M32,0) -> 0 | Q32: =IFERROR(O32*P32,0) -> 0 | T32: =IFERROR(R32*S32,0) -> 0 | W32: =IFERROR(U32*V32,0) -> 0 | Z32: =IFERROR(X32*Y32,0) -> 0 | AC32: =IFERROR(AA32*AB32,0) -> 0 | AF32: =IFERROR(AD32*AE32,0) -> 0 | AG32: =F32+I32+L32+O32+R32+U32+X32+AA32+AD32 -> 220 | AH32: =H32+K32+N32+Q32+T32+W32+Z32+AC32+AF32 -> 7700 | AI32: =IFERROR(AH32/AG32,E32) -> 35
A33: OTHERS
A34: OT001 | B34: Burger Takeaway Box | C34: Packaging | D34: Pcs | E34: ='Item Master'!E33 -> 8 | F34: 400 | G34: 8 | H34: =IFERROR(F34*G34,0) -> 3200 | K34: =IFERROR(I34*J34,0) -> 0 | N34: =IFERROR(L34*M34,0) -> 0 | Q34: =IFERROR(O34*P34,0) -> 0 | T34: =IFERROR(R34*S34,0) -> 0 | W34: =IFERROR(U34*V34,0) -> 0 | Z34: =IFERROR(X34*Y34,0) -> 0 | AC34: =IFERROR(AA34*AB34,0) -> 0 | AF34: =IFERROR(AD34*AE34,0) -> 0 | AG34: =F34+I34+L34+O34+R34+U34+X34+AA34+AD34 -> 400 | AH34: =H34+K34+N34+Q34+T34+W34+Z34+AC34+AF34 -> 3200 | AI34: =IFERROR(AH34/AG34,E34) -> 8
A35: OT002 | B35: Pizza Takeaway Box | C35: Packaging | D35: Pcs | E35: ='Item Master'!E34 -> 15 | F35: 300 | G35: 15 | H35: =IFERROR(F35*G35,0) -> 4500 | K35: =IFERROR(I35*J35,0) -> 0 | N35: =IFERROR(L35*M35,0) -> 0 | Q35: =IFERROR(O35*P35,0) -> 0 | T35: =IFERROR(R35*S35,0) -> 0 | W35: =IFERROR(U35*V35,0) -> 0 | Z35: =IFERROR(X35*Y35,0) -> 0 | AC35: =IFERROR(AA35*AB35,0) -> 0 | AF35: =IFERROR(AD35*AE35,0) -> 0 | AG35: =F35+I35+L35+O35+R35+U35+X35+AA35+AD35 -> 300 | AH35: =H35+K35+N35+Q35+T35+W35+Z35+AC35+AF35 -> 4500 | AI35: =IFERROR(AH35/AG35,E35) -> 15
A36: OT003 | B36: Paper Napkins | C36: Consumables | D36: Pcs | E36: ='Item Master'!E35 -> 1 | H36: =IFERROR(F36*G36,0) -> 0 | K36: =IFERROR(I36*J36,0) -> 0 | N36: =IFERROR(L36*M36,0) -> 0 | Q36: =IFERROR(O36*P36,0) -> 0 | T36: =IFERROR(R36*S36,0) -> 0 | W36: =IFERROR(U36*V36,0) -> 0 | Z36: =IFERROR(X36*Y36,0) -> 0 | AC36: =IFERROR(AA36*AB36,0) -> 0 | AF36: =IFERROR(AD36*AE36,0) -> 0 | AG36: =F36+I36+L36+O36+R36+U36+X36+AA36+AD36 -> 0 | AH36: =H36+K36+N36+Q36+T36+W36+Z36+AC36+AF36 -> 0 | AI36: =IFERROR(AH36/AG36,E36) -> 1
A37: OT004 | B37: Disposable Straws | C37: Consumables | D37: Pcs | E37: ='Item Master'!E36 -> 1 | H37: =IFERROR(F37*G37,0) -> 0 | K37: =IFERROR(I37*J37,0) -> 0 | N37: =IFERROR(L37*M37,0) -> 0 | Q37: =IFERROR(O37*P37,0) -> 0 | T37: =IFERROR(R37*S37,0) -> 0 | W37: =IFERROR(U37*V37,0) -> 0 | Z37: =IFERROR(X37*Y37,0) -> 0 | AC37: =IFERROR(AA37*AB37,0) -> 0 | AF37: =IFERROR(AD37*AE37,0) -> 0 | AG37: =F37+I37+L37+O37+R37+U37+X37+AA37+AD37 -> 0 | AH37: =H37+K37+N37+Q37+T37+W37+Z37+AC37+AF37 -> 0 | AI37: =IFERROR(AH37/AG37,E37) -> 1
A38: OT005 | B38: White Sugar | C38: Pantry & Dry Goods | D38: Kg | E38: ='Item Master'!E37 -> 60 | F38: 45 | G38: 60 | H38: =IFERROR(F38*G38,0) -> 2700 | K38: =IFERROR(I38*J38,0) -> 0 | N38: =IFERROR(L38*M38,0) -> 0 | Q38: =IFERROR(O38*P38,0) -> 0 | T38: =IFERROR(R38*S38,0) -> 0 | W38: =IFERROR(U38*V38,0) -> 0 | Z38: =IFERROR(X38*Y38,0) -> 0 | AC38: =IFERROR(AA38*AB38,0) -> 0 | AF38: =IFERROR(AD38*AE38,0) -> 0 | AG38: =F38+I38+L38+O38+R38+U38+X38+AA38+AD38 -> 45 | AH38: =H38+K38+N38+Q38+T38+W38+Z38+AC38+AF38 -> 2700 | AI38: =IFERROR(AH38/AG38,E38) -> 60
